Workbook

Sheet Introduction
A1: NOTICE | H1: Status color coding | J1: Version control
H2: Column complete | J2: This document is under version B
A3: This is a draft product not yet intended for public release. | H3: Column missing info, see comment | J3: Version B branched from version A at EoD 2026-01-15 savepoint to revert sort mistakes that broke associations later
A4: The material contained in this product is neither complete nor | H4: Cell-specific question/problem
A5: warranted to be free of errors. | H5: In progress
A7: Introduction
A8: Purpose
A9: This document will serve as a centralized database of all contaminants detected in the various monitoring efforts surrounding the Red Hill Water Crisis.
A10: This document will aid researchers by:
B11: Providing a cross-reference between all data sets/data files that contain detections of speecific analytes
B12: Providing references to background information about the sources, uses, and characteristics of certain analytes
B13: Collecting other relevant information that may be helpful to researchers.
A14: This document will aid the public by serving as the foundation for a public-facing contaminant glossary to be hosted on the Red Hill Info Hub website.
A16: Layout
A17: Each row corresponds to a unique analyte.
A18: Information under the heading "Identification" corresponds to ways to uniquely identify this specific analyte, down to the level of relevant stereochemistry. This includes:
B19: Name as given in datasets
B20: Name simplified for sorting
C21: To simplify names for sorting, move locants, isomer designators, etc. to the end of the name and connect with a comma. For example, "1-bromobutane" becomes "bromobutane, 1-".
C22: This allows similar compounds to sort together - for example, "1,1-dichloroethane", "1,1-dichloropropane", and "1,2-dichloroethane" sorts in that order, while the simplified names sort the two dichloroethanes together.
B23: "a.k.a.s" - trade names, common names, or IUPAC preferred names
B24: CASRN - the Chemical Abstracts Service Registry Number is a unique identifier given to a specific substance that is used to specifically identify it among all similarly-named substances.
A25: Information under the heading "Classification" is used to group analytes as members of specific classes. This includes:
B26: Classification at three levels (work in progress, will create a graphic to illustrate classification scheme)
B27: Membership in various groups (true/false)
C28: BTEXMN - benzene, toluene, ethylbenzene, xylenes, methylnaphthalenes, and naphthalene
C29: DBP - disinfection byproducts
C30: Known JP-5 component - something known to be added to JP-5 based on literature or experimental reports of its presence and/or the relevant MILSPEC
D31: Compounds marked TRUE have definitive evidence of their presence in JP-5 (has been detected in experimental samples unambiguously)
D32: Compounds marked Possible have convincing evidence of their presence in JP-5
C33: PAH - polycyclic aromatic hydrocarbons
C34: Pesticides (includes herbicides) (see footnote D)
A35: Information under the heading "Atom & functional group inventory" is used to group analytes by chemical similarity.
A36: This is potentially useful for both chemists and health researchers - e.g., this allows for sorting to find all aldehydes.
A37: Information includes:
B38: Atom inventory - counts of chemically relevant atoms
C39: Carbon - for sorting by carbon range
C40: Nitrogen - for potential reactivity
C41: Halogens - potentially interesting as DBPs or particularlly hazardous materials
B42: Functional group inventory - counts of specific moieties
...

Sheet Glossary
A1: Compound name given in datasets | B1: Compound name for sorting | C1: Chemical formula | D1: a.k.a.s | E1: CASRN | F1: InChIKey | G1: Primary | H1: Secondary | I1: Tertiary | J1: Aromatic | K1: BTEXMN | L1: DBP | M1: Known JP-5 component | N1: PAH | O1: Pesticide | P1: C | Q1: N | R1: F | S1: Cl | T1: Br | U1: 1° alcohols | V1: 2° alcohols | W1: 3° alcohols | X1: Ethers | Y1: Ketones | Z1: Aldehydes | AA1: Esters | AB1: Epoxides | AC1: Amines | AD1: Halogenated | AE1: Saturated | AF1: NPDWR MCLG (mg/L) | AG1: NPDWR MCL (mg/L) | AH1: NPDWR notes | AI1: SMCL (mg/L) | AJ1: CCL5 | AK1: HDOH MCL (mg/L) | AL1: HDOH more stringent | AM1: Montreal Protocol | AN1: Stockholm Convention | AO1: Sources | AP1: Notes | AQ1: Footnotes | AR1: Immediate | AS1: Flushing reports | AT1: LTM plan | AU1: EDWM plan | AV1: SafeWaters data (old scrape) | AW1: SafeWaters data (checking 2026-06-22)
A2: 2-(2-methoxyethoxy)ethanol | B2: 2-(2-methoxyethoxy)ethanol | C2: C5H12O3 | D2: diethylene glycol monomethyl ether | diglycol monomethyl ether | methoxydiglycol | methylcarbitol | E2: 111-77-3 | F2: SBASXUCJHJRPEV-UHFFFAOYSA-N | G2: Glycol ether | M2: TRUE | P2: 5 | Q2: 0 | R2: 0 | S2: 0 | T2: 0 | U2: 1 | X2: 2 | AD2: =OR(Glossary!$R2>0,Glossary!$S2>0,Glossary!$T2>0) -> FALSE | AE2: TRUE | AL2: =IF(ISBLANK(AK2),"",AK2<AG2) | AO2: 2-(2-methoxyethoxy)ethanol is a chemical compound used as a fuel system icing inhibitor in jet fuels and as an industrial solvent in construction products (paints/stains, caulks/sealants), cosmetic products, high-strength cleansers, automotive fluids, and certain inks. | AR2: TRUE | AU2: TRUE | AV2: TRUE
A3: Acenaphthene | B3: acenaphthene | C3: C12H10 | D3: peri-ethylenenaphthalene | E3: 83-32-9 | F3: CWRYPZZKDGJXCA-UHFFFAOYSA-N | G3: Aromatic | H3: PAH | I3: Naphthalene, alkylated | J3: TRUE | N3: TRUE | P3: 12 | Q3: 0 | R3: 0 | S3: 0 | T3: 0 | AD3: =OR(Glossary!$R3>0,Glossary!$S3>0,Glossary!$T3>0) -> FALSE | AE3: FALSE | AL3: =IF(ISBLANK(AK3),"",AK3<AG3) | AO3: Acenaphthene is a C12 PAH produced during combustion and manufactured for industrial uses. Combustion sources include the burning of fossil fuels, forest fires, volcanic eruptions, and charbroiling of food. Industrially, it is an intermediate used in the production of dyes, plastics, biocides, and pharmaceutical products. | AQ3: A | AR3: TRUE
A4: Acenaphthylene | B4: acenaphthylene | C4: C12H8 | D4: cyclopenta[de]naphthalene | E4: 208-96-8 | F4: HXGDTGSAIMULJN-UHFFFAOYSA-N | G4: Aromatic | H4: PAH | I4: Naphthalene, alkylated | J4: TRUE | N4: TRUE | O4: TRUE | P4: 12 | Q4: 0 | R4: 0 | S4: 0 | T4: 0 | AD4: =OR(Glossary!$R4>0,Glossary!$S4>0,Glossary!$T4>0) -> FALSE | AE4: FALSE | AL4: =IF(ISBLANK(AK4),"",AK4<AG4) | AO4: Acenaphthylene is a C12 PAH produced during combustion and also manufactured for industrial uses. Combustion sources include the burning of fossil fuels, forest fires, volcanic eruptions, and charbroiling of food. It is used in insecticides, fungicides, and as an intermediate in the manufacture of dyes and plastics. | AQ4: A | AR4: TRUE | AU4: TRUE | AV4: TRUE
A5: Alachlor | B5: Alachlor | C5: C14H20ClNO2 | E5: 15972-60-8 | F5: XCSGPAVHZFQHGE-UHFFFAOYSA-N | G5: Aromatic | H5: Benzene | I5: Derivatized | J5: TRUE | O5: TRUE | P5: 14 | Q5: 1 | R5: 0 | S5: 1 | T5: 0 | AD5: =OR(Glossary!$R5>0,Glossary!$S5>0,Glossary!$T5>0) -> TRUE | AE5: FALSE | AF5: 0 | AG5: 0.002 | AK5: 0.002 | AL5: =IF(ISBLANK(AK5),"",AK5<AG5) -> FALSE | AO5: Alachlor is a synthetic herbicide used in agriculture. It has been used extensively in pre-emergent weed control formulations in crops such as corn, sorghum, and soybeans. It enters drinking water primarily from agricultural runoff. | AR5: TRUE
A6: Anthracene | B6: anthracene | C6: C14H10 | E6: 120-12-7 | F6: MWPLVEDNUUSJAV-UHFFFAOYSA-N | G6: Aromatic | H6: PAH | I6: Anthracene | J6: TRUE | M6: TRUE | N6: TRUE | P6: 14 | Q6: 0 | R6: 0 | S6: 0 | T6: 0 | AD6: =OR(Glossary!$R6>0,Glossary!$S6>0,Glossary!$T6>0) -> FALSE | AE6: FALSE | AL6: =IF(ISBLANK(AK6),"",AK6<AG6) | AO6: Anthracene is a diesel-range PAH (C14) found in coal tar and produced by incomplete combustion processes. It is used in production of dyes and as a component of synthetic fibers and plastics. It occurs in tobacco smoke, vehicle emissions, and other combustion gasses, and is found in surface waters, waste waters, and lake sediments. | AQ6: A | AR6: TRUE | AU6: TRUE | AV6: TRUE
A7: Antimony | B7: antimony | C7: Sb | E7: 7440-36-0 | F7: WATWJIUSRGPENY-UHFFFAOYSA-N | G7: Pure element | H7: Metalloid | I7: Pnictogen (nitrogen group) | P7: 0 | Q7: 0 | R7: 0 | S7: 0 | T7: 0 | AD7: =OR(Glossary!$R7>0,Glossary!$S7>0,Glossary!$T7>0) -> FALSE | AE7: N/A | AF7: 0.006 | AG7: 0.006 | AL7: =IF(ISBLANK(AK7),"",AK7<AG7) | AO7: Antimony is a chemical element found naturally in the form of the mineral stibnite (antimony trisulfide). Pure antimony is used in alloys for solders and a variety of metals, while antimony-containing compounds are commonly used in fire retardants, plastics, textiles, rubber, adhesives, ceramics, paint, and paper. Antimony is also found in petroleum products and most often contaminates drinking water by discharge from petroleum refineries. | AQ7: B | AR7: TRUE | AT7: TRUE | AV7: TRUE
A8: Arsenic | B8: arsenic | C8: As | E8: 7440-38-2 | F8: RQNWIZPPADIBDY-UHFFFAOYSA-N | G8: Pure element | H8: Metalloid | I8: Pnictogen (nitrogen group) | O8: TRUE | P8: 0 | Q8: 0 | R8: 0 | S8: 0 | T8: 0 | AD8: =OR(Glossary!$R8>0,Glossary!$S8>0,Glossary!$T8>0) -> FALSE | AE8: N/A | AF8: 0 | AG8: 0.01 | AK8: 0.01 | AL8: =IF(ISBLANK(AK8),"",AK8<AG8) -> FALSE | AO8: Arsenic is a chemical element used in rat poison, agricultural insecticides, pesticides, and herbicides. Small amounts of arsenic are used in the production of electronics. Major sources in drinking water include naturally-occurring mineral deposits, orchard runoff, and industrial runoff from glass and electronics production. | AQ8: B | AR8: TRUE | AT8: TRUE | AV8: TRUE
A9: Atrazine | B9: Atrazine | C9: C8H14ClN5 | D9: AAtrex | Atranex | Atratol | Atred | Atrex | Attrex | Fenatrol | Griffex | Mebazine | Primatol A | Vectral SC | Weedex | E9: 1912-24-9 | F9: MXWJVTOOROXGIU-UHFFFAOYSA-N | G9: Aromatic | H9: Triazine | J9: TRUE | O9: TRUE | P9: 8 | Q9: 5 | R9: 0 | S9: 1 | T9: 0 | AD9: =OR(Glossary!$R9>0,Glossary!$S9>0,Glossary!$T9>0) -> TRUE | AE9: FALSE | AF9: 0.003 | AG9: 0.003 | AK9: 0.003 | AL9: =IF(ISBLANK(AK9),"",AK9<AG9) -> FALSE | AO9: Atrazine is a synthetic herbicide widely used to control broadleaf weeds and grasses in agricultural crops. It enters the environment and drinking water supplies through agricultural application, runoff and leaching into groundwater and surface water. | AR9: TRUE
A10: Barium | B10: barium | C10: Ba | E10: 7440-39-3 | F10: DSAJWYNOEDNPEQ-UHFFFAOYSA-N | G10: Pure element | H10: Metal | I10: Alkaline earth metal | M10: TRUE | P10: NA | Q10: NA | R10: NA | S10: NA | T10: NA | AD10: =OR(Glossary!$R10>0,Glossary!$S10>0,Glossary!$T10>0) -> TRUE | AE10: N/A | AF10: 2 | AG10: 2 | AK10: 2 | AL10: =IF(ISBLANK(AK10),"",AK10<AG10) -> FALSE | AO10: Barium is a chemical element that is commonly used as a filler for rubber, plastics, and resins. Some of its compounds are used in signal flares, fireworks, drilling fluid, X-ray radiocontrast agents, and rodenticides. It is released from drilling and metal refining operations, and by erosion of natural mineral deposits. | AQ10: B | AR10: TRUE | AT10: TRUE | AV10: TRUE
A11: Benzene | B11: benzene | C11: C6H6 | D11: C6H6 | benzol | benzole | benzolene | E11: 71-43-2 | F11: UHOVQNZJYSORNB-UHFFFAOYSA-N | G11: Aromatic | H11: Benzene | J11: TRUE | K11: TRUE | M11: TRUE | P11: 6 | Q11: 0 | R11: 0 | S11: 0 | T11: 0 | AD11: =OR(Glossary!$R11>0,Glossary!$S11>0,Glossary!$T11>0) -> FALSE | AE11: FALSE | AF11: 0 | AG11: 0.005 | AL11: =IF(ISBLANK(AK11),"",AK11<AG11) | AO11: Benzene is a gasoline range aromatic hydrocarbon (C6) found in petroleum and used as a solvent for fats, oils, inks, paints, rubber, and plastics, and as a chemical intermediate in the manufacture of detergents, explosives, pharmaceuticals, and dyestuffs. Benzene enters water sources via industrial discharge as well as leaching from fuel storage tanks and landfills. | AR11: TRUE | AT11: TRUE | AU11: TRUE | AV11: TRUE
A12: Benzo (a) anthracene | B12: benzo[a]anthracene | C12: C18H12 | D12: benz[a]anthracene | benzanthrene | tetraphene | E12: 56-55-3 | F12: DXBHBZVCASKNBY-UHFFFAOYSA-N | G12: Aromatic | H12: PAH | J12: TRUE | N12: TRUE | P12: 18 | Q12: 0 | R12: 0 | S12: 0 | T12: 0 | AD12: =OR(Glossary!$R12>0,Glossary!$S12>0,Glossary!$T12>0) -> FALSE | AE12: FALSE | AL12: =IF(ISBLANK(AK12),"",AK12<AG12) | AO12: Benzo[a]anthracene is a diesel-range PAH (C18) produced from incomplete combustion of organic materials and found in coal tar, roasted coffee, tobacco smoke, smoked foods, and automobile exhaust. There are no known uses of this compound other than research and it is not produced at scale. | AQ12: A | AR12: TRUE
A13: Benzo (a) pyrene | B13: benzo[a]pyrene | C13: C20H12 | D13: B(a)P | 3,4-BP | 3,4-Benzopyrene | 3,4-Benzpyrene | BP | benzo[a]pyrene | benzo[def]chrysene | benzo[pqr]tetraphene | benzpyrene | E13: 50-32-8 | F13: FMMWHPNWAFZXNH-UHFFFAOYSA-N | G13: Aromatic | H13: PAH | J13: TRUE | N13: TRUE | P13: 20 | Q13: 0 | R13: 0 | S13: 0 | T13: 0 | AD13: =OR(Glossary!$R13>0,Glossary!$S13>0,Glossary!$T13>0) -> FALSE | AE13: FALSE | AF13: 0 | AG13: 0.0002 | AK13: 0.0002 | AL13: =IF(ISBLANK(AK13),"",AK13<AG13) -> FALSE | AO13: Benzo[a]pyrene is a diesel-range PAH (C20) commonly found in coal tar. It is also found in tobacco smoke, vehicle exhaust, industrial emissions, and many foods such as grilled meats, as it is produced from incomplete combustion of organic materials. Benzo[a]pyrene is found in and leaches from asphalt that was historically used to line water storage tanks and distribution lines, which is its primary source as a drinking water contaminant. | AQ13: A | AR13: TRUE | AT13: TRUE | AU13: TRUE | AV13: TRUE
A14: Benzo (b) fluoranthene | B14: benzo[b]fluoranthene | C14: C20H12 | D14: 2,3-Benzfluoranthene | 2,3-Benzofluoranthene | 3,4-Benzfluoranthene | B(b)F | BF | Benz(e)acephenanthrylene | Benzo(''b'')fluoranthene | benz[e]acephenanthrylene | E14: 205-99-2 | F14: FTOVXSOBNPWTSH-UHFFFAOYSA-N | G14: Aromatic | H14: PAH | J14: TRUE | N14: TRUE | P14: 20 | Q14: 0 | R14: 0 | S14: 0 | T14: 0 | AD14: =OR(Glossary!$R14>0,Glossary!$S14>0,Glossary!$T14>0) -> FALSE | AE14: FALSE | AL14: =IF(ISBLANK(AK14),"",AK14<AG14) | AO14: Benzo[b]fluoranthene is a diesel-range PAH (C20) commonly found in fossil fuels and petroleum products. It is also found in tobacco smoke, vehicle exhaust, and industrial emissions as it is produced from incomplete combustion of organic materials. | AQ14: A | AR14: TRUE | AU14: TRUE | AV14: TRUE
A15: Benzo (g,h,i) perylene | B15: benzo[ghi]perhylene | C15: C22H12 | D15: 1,12-benzoperylene | benzo(ghi)perilene | E15: 191-24-2 | F15: GYFAGKUZYNFMBN-UHFFFAOYSA-N | G15: Aromatic | H15: PAH | J15: TRUE | N15: TRUE | P15: 22 | Q15: 0 | R15: 0 | S15: 0 | T15: 0 | AD15: =OR(Glossary!$R15>0,Glossary!$S15>0,Glossary!$T15>0) -> FALSE | AE15: FALSE | AL15: =IF(ISBLANK(AK15),"",AK15<AG15) | AO15: Benzo[ghi]perylene is a diesel-range PAH (C22) commonly found in coal tar and crude oil. It is also found in tobacco smoke, vehicle exhaust, and industrial emissions as it is produced from incomplete combustion of organic materials. | AQ15: A | AR15: TRUE | AU15: TRUE | AV15: TRUE
A16: Benzo (k) fluoranthene | B16: benzo[k]fluoranthene | C16: C20H12 | D16: 11,12-Benzofluoranthene | Benzo(''k'')fluoranthene | E16: 207-916-6 | F16: HAXBIWFMXWRORI-UHFFFAOYSA-N | G16: Aromatic | H16: PAH | J16: TRUE | N16: TRUE | P16: 20 | Q16: 0 | R16: 0 | S16: 0 | T16: 0 | AD16: =OR(Glossary!$R16>0,Glossary!$S16>0,Glossary!$T16>0) -> FALSE | AE16: FALSE | AL16: =IF(ISBLANK(AK16),"",AK16<AG16) | AO16: Benzo[k]fluoranthene is a diesel-range PAH (C20) commonly found in coal tar and crude oil. It is also found in tobacco smoke, vehicle exhaust, and industrial emissions as it is produced from incomplete combustion of organic materials. | AQ16: A | AR16: TRUE | AU16: TRUE | AV16: TRUE
A17: Dibenzo (a,h) anthracene | B17: benzo[k]tetraphene | C17: C22H14 | D17: dibenzo[a,h]anthracene | DBA | E17: 53-70-3 | F17: LHRCREOYAASXPZ-UHFFFAOYSA-N | G17: Aromatic | H17: PAH | J17: TRUE | N17: TRUE | P17: 22 | Q17: 0 | R17: 0 | S17: 0 | T17: 0 | AD17: =OR(Glossary!$R17>0,Glossary!$S17>0,Glossary!$T17>0) -> FALSE | AE17: FALSE | AL17: =IF(ISBLANK(AK17),"",AK17<AG17) | AO17: Benzo[k]tetraphene is a diesel-range PAH (C22) commonly found in coal tar and crude oil. It is also found in tobacco smoke, vehicle exhaust, and industrial emissions as it is produced from incomplete combustion of organic materials. | AQ17: A | AR17: TRUE | AU17: TRUE | AV17: TRUE
A18: Beryllium | B18: beryllium | C18: Be | E18: 7440-41-7 | F18: ATBAMAFKBVZNFJ-UHFFFAOYSA-N | G18: Pure element | H18: Metal | I18: Alkaline earth metal | P18: 0 | Q18: 0 | R18: 0 | S18: 0 | T18: 0 | AD18: =OR(Glossary!$R18>0,Glossary!$S18>0,Glossary!$T18>0) -> FALSE | AE18: N/A | AF18: 0.004 | AG18: 0.004 | AL18: =IF(ISBLANK(AK18),"",AK18<AG18) | AO18: Beryllium is a chemical element naturally found in minerals, rocks, coal, soil, and volcanic dust. Its alloys with other metals are used as electrical components, tools, and structural components, especially in aircraft, missiles, and satellites. Beryllium can contaminate drinking water sources by release from industrial operations (coal-burning power plants and factories and the metal refining, electrical, aerospace, and defense industries). | AR18: TRUE | AT18: TRUE | AV18: TRUE
A19: Bis(2-ethylhexyl)adipate | B19: bis(2-ethylhexyl)adipate | C19: C22H42O4 | D19: BEHA | DEHA | diethylhexyl adipate | E19: 103-23-1 | F19: SAOKZLXYCUGLFA-UHFFFAOYSA-N | G19: Aliphatic | H19: Alkane | I19: Branched | P19: 22 | Q19: 0 | R19: 0 | S19: 0 | T19: 0 | AA19: 2 | AD19: =OR(Glossary!$R19>0,Glossary!$S19>0,Glossary!$T19>0) -> FALSE | AE19: FALSE | AF19: 0.4 | AG19: 0.4 | AK19: 0.4 | AL19: =IF(ISBLANK(AK19),"",AK19<AG19) -> FALSE | AO19: A synthetic organic compound widely used as a plasticizer to increase flexibility in plastics, particularly in polyvinyl chloride (PVC) food-packaging materials. As a solvent it is used as a component of aircraft lubricants and in hydraulic fluids. Bis(2-ethylhexyl)adipate contaminates drinking water through discharge from chemical factories. | AR19: TRUE
A20: Bis(2-ethylhexyl)phthalate | B20: bis(2-ethylhexyl)phthalate | C20: C24H38O4 | D20: DEHP | diethylhexyl phthalate | E20: 117-81-7 | F20: BJQHLKABXJIVAM-UHFFFAOYSA-N | G20: Aromatic | H20: Benzene | I20: Derivatized | J20: TRUE | P20: 24 | Q20: 0 | R20: 0 | S20: 0 | T20: 0 | AA20: 2 | AD20: =OR(Glossary!$R20>0,Glossary!$S20>0,Glossary!$T20>0) -> FALSE | AE20: FALSE | AF20: 0 | AG20: 0.006 | AK20: 0.006 | AL20: =IF(ISBLANK(AK20),"",AK20<AG20) -> FALSE | AO20: Bis(2-ethylhexyl)phthalate is a synthetic organic compound widely used as a plasticizer to increase flexibility in plastics, particularly in polyvinyl chloride (PVC). It is also used as a hydraulic fluid and dielectric fluid in electrical capacitors. Bis(2-ethylhexyl)phthalate contaminates drinking water through discharge from chemical factories. | AR20: TRUE | AT20: TRUE | AV20: TRUE
A21: Bromate | B21: bromate | C21: BrO3 − | E21: 15541-45-4 | F21: SXDBWCPKPHAZSM-UHFFFAOYSA-M | G21: Inorganic compound | L21: TRUE | P21: 0 | Q21: 0 | R21: 0 | S21: 0 | T21: 0 | AD21: TRUE | AE21: FALSE | AF21: 0 | AG21: 0.01 | AL21: =IF(ISBLANK(AK21),"",AK21<AG21) | AO21: Bromate is an ion composed of bromine and oxygen. Bromate-containing compounds have a variety of uses, but it is present in drinking water most commonly as a disinfection byproduct produced by reaction of ozone, used as an anti-microbial treatment, with naturally occurring bromide. | AU21: TRUE | AW21: TRUE
A22: Bromide | B22: bromide | C22: Br − | E22: 24959-67-9 | F22: CPELXLSAUQHCOX-UHFFFAOYSA-M | G22: Pure element | H22: Nonmetal | I22: Halogen | P22: 0 | Q22: 0 | R22: 0 | S22: 0 | T22: 1 | AD22: TRUE | AE22: N/A | AL22: =IF(ISBLANK(AK22),"",AK22<AG22) | AO22: Bromide is the anionic (negatively charged) form of bromine, a chemical element and halogen. It is most commonly found in seawater, some fossil fuels, and some relatively rarae minerals. In coastal regions, bromide levels in groundwater are usually higher than in inland areas, owing to seawater intrusion into the groundwater aquifer. Bromide in a water source can form bromine-containing disinfection byproducts when water is treated with an oxidizer such as free chlorine to kill microbes. | AU22: TRUE | AW22: TRUE
A23: Bromobenzene | B23: bromobenzene | C23: C6H5Br | D23: PhBr | monobromobenzene | phenyl bromide | E23: 108-86-1 | F23: QARVLSVVCXYDNA-UHFFFAOYSA-N | G23: Aromatic | H23: Benzene | I23: Halogenated | J23: TRUE | P23: 6 | Q23: 0 | R23: 0 | S23: 0 | T23: 1 | AD23: =OR(Glossary!$R21>0,Glossary!$S21>0,Glossary!$T21>0) -> FALSE | AE23: FALSE | AL23: =IF(ISBLANK(AK23),"",AK23<AG23) | AO23: Bromobenzene is an organic compound commonly used as a solvent for large scale crystallization and as a reagent in organic synthesis. It is mainly found in chemical laboratories and industrial manufacturing processes, and is used in the production of pharmaceuticals and other organic chemicals. | AR23: TRUE
A24: Bromochloromethane | B24: bromochloromethane | C24: CH2BrCl | D24: CB | CBM | Chlorobromomethane | Fluorocarbon 1011 | Halon 1011 | Methyl chlorobromide | chloromethyl bromide | monochloromonobromomethane | E24: 74-97-5 | F24: JPOXNPPZZKNXOV-UHFFFAOYSA-N | G24: Aliphatic | H24: Alkane | I24: Linear | P24: 1 | Q24: 0 | R24: 0 | S24: 1 | T24: 1 | AD24: =OR(Glossary!$R22>0,Glossary!$S22>0,Glossary!$T22>0) -> TRUE | AE24: TRUE | AL24: =IF(ISBLANK(AK24),"",AK24<AG24) | AO24: Bromochloromethane is a synthetic organic compound that is primarily used as a fire-extinguishing agent, as a solvent, and as an intermediate in the manufacture of some insecticides. It is mainly found in industrial fire protection systems and equipment. | AR24: TRUE
A25: Bromodichloromethane | B25: bromodichloromethane | C25: CHBrCl2 | E25: 75-27-4 | F25: FMWLUWPQPKEARP-UHFFFAOYSA-N | G25: Aliphatic | H25: Alkane | I25: Linear | L25: TRUE | P25: 1 | Q25: 0 | R25: 0 | S25: 2 | T25: 1 | AD25: =OR(Glossary!$R23>0,Glossary!$S23>0,Glossary!$T23>0) -> TRUE | AE25: TRUE | AF25: 0 | AH25: MCL as a class, see TTHMs | AL25: =IF(ISBLANK(AK25),"",AK25<AG25) | AO25: Bromodichloromethane is a synthetic organic compound and trihalomethane commonly formed as a disinfection byproduct when chlorine is used to treat water. It is also used as a reagent and intermediate in organic synthesis, as a fire extinguishing agent, a solvent for fats, waxes, and resins, and as a heavy liquid for mineral and salt separations. | AR25: TRUE | AV25: TRUE
A26: Bromoform | B26: bromoform | C26: CHBr3 | D26: tribromomethane | E26: 75-25-2 | F26: DIKBFYAXUHHXCS-UHFFFAOYSA-N | G26: Aliphatic | H26: Alkane | I26: Linear | L26: TRUE | P26: 1 | Q26: 0 | R26: 0 | S26: 0 | T26: 3 | AD26: =OR(Glossary!$R24>0,Glossary!$S24>0,Glossary!$T24>0) -> TRUE | AE26: TRUE | AF26: 0 | AH26: MCL as a class, see TTHMs | AL26: =IF(ISBLANK(AK26),"",AK26<AG26) | AO26: Bromoform is an organic compound and trihalomethane formed naturally by marine algae. It has been used as a solvent for waxes and oils, and in shipbuilding, aircraft, and aerospace industries and as a fire-suppressing chemical in fire extinguishers. In drinking water, bromoform is produced as a disinfection byproduct when certain disinfectants react with bromide naturally present in the source water. | AR26: TRUE | AV26: TRUE
A27: Bromomethane | B27: bromomethane | C27: CH3Br | D27: Embafume | Halon 1001 | methyl bromide | E27: 74-83-9 | F27: GZUXJHMPEANEGY-UHFFFAOYSA-N | G27: Aliphatic | H27: Alkane | I27: Linear | O27: TRUE | P27: 1 | Q27: 0 | R27: 0 | S27: 0 | T27: 1 | AD27: =OR(Glossary!$R25>0,Glossary!$S25>0,Glossary!$T25>0) -> TRUE | AE27: TRUE | AL27: =IF(ISBLANK(AK27),"",AK27<AG27) | AM27: TRUE | AO27: Bromomethane is an organic compound produced naturally in small amounts by algae and kelp, and it is widely used as a soil fumigant and pesticide in agriculture. It is also used in industrial applications including chemical synthesis and as a refrigerant and fire extinguishing agent | AR27: TRUE
A28: 2-Butanone | B28: butanone, 2- | C28: C4H8O | D28: 2-butanone | methyl ethyl ketone | MEK | butan-2-one | ethyl methyl ketone | methyl acetone | oxobutane | E28: 78-93-3 | F28: ZWEHNKRNPOVVGH-UHFFFAOYSA-N | G28: Aliphatic | H28: Alkane | I28: Linear | P28: 4 | Q28: 0 | R28: 0 | S28: 0 | T28: 0 | Y28: 1 | AD28: =OR(Glossary!$R26>0,Glossary!$S26>0,Glossary!$T26>0) -> TRUE | AE28: FALSE | AL28: =IF(ISBLANK(AK28),"",AK28<AG28) | AO28: 2-butanone is a common organic solvent used in processes involving gums, resins, cellulose materials, and surface coatings, and found in products like paints, varnishes, adhesives, and cleaning agents. It is also used in the synthetic rubber, plastics, and textiles industries, and for degreasing and oil extraction applications. | AR28: TRUE
A29: n-Butylbenzene | B29: butylbenzene, n- | C29: C10H14 | D29: 1-phenylbutane | butylbenzene | E29: 104-51-8 | F29: OCKPCBLVNKHBMX-UHFFFAOYSA-N | G29: Aromatic | H29: Benzene | I29: Alkylated | J29: TRUE | P29: 10 | Q29: 0 | R29: 0 | S29: 0 | T29: 0 | AD29: =OR(Glossary!$R27>0,Glossary!$S27>0,Glossary!$T27>0) -> TRUE | AE29: FALSE | AL29: =IF(ISBLANK(AK29),"",AK29<AG29) | AO29: n-butylbenzene is a C10 aromatic hydrocarbon used in organic synthesis (including pesticide manufacturing), as a solvent for coating materials, and as a plasticizer, surface active agent, and polymer linking agent in plastic production. It is commonly found in asphalt and naphtha. | AR29: TRUE | AU29: TRUE | AV29: TRUE
A30: sec-Butylbenzene | B30: butylbenzene, s- | C30: C10H14 | D30: (1-Methylpropyl)benzene | 2-Phenylbutane | s-butylbenzene | secondary butylbenzene | E30: 135-98-8 | F30: ZJMWRROPUADPEA-UHFFFAOYSA-N | G30: Aromatic | H30: Benzene | I30: Alkylated | J30: TRUE | P30: 10 | Q30: 0 | R30: 0 | S30: 0 | T30: 0 | AD30: =OR(Glossary!$R28>0,Glossary!$S28>0,Glossary!$T28>0) -> FALSE | AE30: FALSE | AL30: =IF(ISBLANK(AK30),"",AK30<AG30) | AO30: sec-butylbenzene is a C10 aromatic hydrocarbon used in organic synthesis, as a solvent for coating materials, and as a plasticizer and surface active agent. It can be found in crude oil, vehicle emissions, ambient air, and may be released heated plastics. | AR30: TRUE | AU30: TRUE | AV30: TRUE
A31: tert-Butylbenzene | B31: butylbenzene, t- | C31: C10H14 | D31: tertiary butylbenzene | t-butylbenzene | 1,1-dimethylethylbenzene | E31: 98-06-6 | F31: YTZKOQUCBOVLHL-UHFFFAOYSA-N | G31: Aromatic | H31: Benzene | I31: Alkylated | J31: TRUE | P31: 10 | Q31: 0 | R31: 0 | S31: 0 | T31: 0 | AD31: =OR(Glossary!$R29>0,Glossary!$S29>0,Glossary!$T29>0) -> FALSE | AE31: FALSE | AL31: =IF(ISBLANK(AK31),"",AK31<AG31) | AO31: tert-butylbenzene is a C10 aromatic hydrocarbon used as a solvent and polymer-linking agent in organic synthesis. It has also been found in landfill gas. | AR31: TRUE | AU31: TRUE | AV31: TRUE
A32: Cadmium | B32: cadmium | C32: Cd | E32: 7440-43-9 | F32: BDOSMKKIYDKNTQ-UHFFFAOYSA-N | G32: Pure element | H32: Metal | I32: Transition metal (group 12) | P32: 0 | Q32: 0 | R32: 0 | S32: 0 | T32: 0 | AD32: =OR(Glossary!$R30>0,Glossary!$S30>0,Glossary!$T30>0) -> FALSE | AE32: N/A | AF32: 0.005 | AG32: 0.005 | AK32: 0.005 | AL32: =IF(ISBLANK(AK32),"",AK32<AG32) -> FALSE | AO32: Cadmium is a chemical element and metal used in electroplating, pigments, batteries, plastics, and corrosion-resistant coatings. It is also used in alloys, solders, Ni-Cd batteries, and nuclear reactor control systems, and can be released into the air through fossil fuel burning and waste incineration. Cadmium can be released into drinking water by corrosion of galvanized piping, erosion of natural minerals, and industrial discharge (metal refining, waste batteries & paints). | AQ32: B | AR32: TRUE | AT32: TRUE | AV32: TRUE
A33: Calcium | B33: calcium | C33: Ca 2+ | E33: 14127-61-8 | 7440-70-2 | F33: BHPQYMZQTOCNFJ-UHFFFAOYSA-N | G33: Pure element | H33: Metal | I33: Alkaline earth metal | P33: 0 | Q33: 0 | R33: 0 | S33: 0 | T33: 0 | AD33: FALSE | AE33: N/A | AL33: =IF(ISBLANK(AK33),"",AK33<AG33) | AO33: Calcium is a chemical element and metal. It is the fifth most abundant element in the earth’s crust and is a major component of many rocks and minerals, including the minerals that make up the shells of shellfish and the exoskeletons of corals. Calcium is an essential dietary mineral and is one of the water components that cause “hard” water. Evidence suggests that elevated calcium in drinking water may actually be beneficial to human health. Calcium in drinking water comes from the erosion of natural calcium-containing minerals. | AQ33: C | AU33: TRUE | AW33: TRUE
A34: Carbon tetrachloride | B34: carbon tetrachloride | C34: CCl4 | D34: carbon chloride | carbon tet | F10 | Freon 10 | Halon 104 |methane tetrachloride | Necatorina | perchloromethane | R10 | Refrigerant R10 | Tetra | Tetrachloromethane | Tetrasol | Thawpit | Univerm | Vermoestricid | tetrachloridocarbon | E34: 56-23-5 | F34: VZGDMQKNWNREIO-UHFFFAOYSA-N | G34: Aliphatic | H34: Alkane | I34: Linear | P34: 1 | Q34: 0 | R34: 0 | S34: 4 | T34: 0 | AD34: =OR(Glossary!$R31>0,Glossary!$S31>0,Glossary!$T31>0) -> FALSE | AE34: TRUE | AF34: 0 | AG34: 0.005 | AL34: =IF(ISBLANK(AK34),"",AK34<AG34) | AM34: TRUE | AO34: Carbon tetrachloride is a chemical compound that is an excellent solvent and was consequently used in a wide variety of applications; used broadly as a solvent, it is also non-flammable and was used as a fire extinguishing fluid, it also found use as a grain fumigant. Owing to its toxicity and environmental impact, especially its ozone-depleting nature, its use today has been greatly curtailed and continuing uses are highly regulated. It is used in the production of refrigerants and as a blowing agent. Carbon tetrachloride contaminantes drinking water through discharge from industrial activities. | AR34: TRUE | AT34: TRUE | AV34: TRUE
A35: Chlorate | B35: chlorate | C35: ClO3 − | E35: 14866-68-3 | F35: XTEGARKTQYYJKE-UHFFFAOYSA-M | G35: Inorganic compound | L35: TRUE | P35: 0 | Q35: 0 | R35: 0 | S35: 1 | T35: 0 | AD35: TRUE | AE35: FALSE | AL35: =IF(ISBLANK(AK35),"",AK35<AG35) | AO35: Chlorate is an ion composed of chlorine and oxygen. It occurs naturally in some minerals and is used in a variety of Chlorate-containing compounds have a variety of uses, but it is present in drinking water most commonly as a disinfection byproduct produced from the use of chlorine dioxide as an anti-microbial water treatment. | AU35: TRUE | AW35: TRUE
A36: alpha-Chlordane | B36: Chlordane, α- | C36: C10H6Cl8 | D36: chlordane, cis- | chlordane, α- | E36: 5103-71-9 | F36: BIWJNBZANLAXMG-IQEDOFJGSA-N | G36: Aliphatic | H36: Alkene | I36: Cyclic | O36: TRUE | P36: 10 | Q36: 0 | R36: 0 | S36: 8 | T36: 0 | AD36: =OR(Glossary!$R32>0,Glossary!$S32>0,Glossary!$T32>0) -> FALSE | AE36: FALSE | AF36: 0 | AG36: 0.002 | AH36: Component of chlordane, which is the regulated pollutant | AK36: 0.002 | AL36: =IF(ISBLANK(AK36),"",AK36<AG36) -> FALSE | AN36: A | AO36: alpha-chlordane is a synthetic compound and component of the pesticide chlordane. It was primarily used to control termites, agricultural pests, and household insects, but is now banned and restricted from use in the United States. Chlordane residue is highly persistent in the environment and is still found contaminating some drinking water sources today despite having been banned since 1988. | AP36: Pure compound, not to be confused with chlordane as a product, which contains chlordane, heptachlor, and nonachlor | AR36: TRUE
A37: gamma-Chlordane | B37: Chlordane, γ- | C37: C10H6Cl8 | D37: chlordane, trans- | chlordane, γ- | chlordane, beta- | chlordane, β- | E37: 5103-74-2 | F37: JBZJEPYXXVKOKF-UHFFFAOYSA-N | G37: Aliphatic | H37: Alkene | I37: Cyclic | O37: TRUE | P37: 10 | Q37: 0 | R37: 0 | S37: 8 | T37: 0 | AD37: =OR(Glossary!$R33>0,Glossary!$S33>0,Glossary!$T33>0) -> FALSE | AE37: FALSE | AF37: 0 | AG37: 0.002 | AH37: Component of chlordane, which is the regulated pollutant | AK37: 0.002 | AL37: =IF(ISBLANK(AK37),"",AK37<AG37) -> FALSE | AN37: A | AO37: gamma-chlordane is a synthetic organochlorine compound and component of the pesticide chlordane. It was primarily used to control termites, agricultural pests, and household insects, but it is now banned or limited to very restricted use and is no longer produced for commercial use in the United States. Chlordane residue is highly persistent in the environment and is still found contaminating some drinking water sources today despite having been banned since 1988. | AP37: Pure compound, not to be confused with chlordane as a product, which contains chlordane, heptachlor, and nonachlor. Note that the nomenclature of chlordane compounds is somewhat sloppy. This compound, referred to by CASRN 5103-74-2, is referred to as both beta- and gamma-Chlordane. A separate compound, CASRN 5566-34-7, is also referred to as gamma-Chlordane, despite being chemically distinct. | AR37: TRUE
A38: Chloride | B38: chloride | C38: Cl − | E38: 15541-45-4 | F38: SXDBWCPKPHAZSM-UHFFFAOYSA-M | G38: Pure element | H38: Nonmetal | I38: Halogen | P38: 0 | Q38: 0 | R38: 0 | S38: 1 | T38: 0 | AD38: TRUE | AE38: N/A | AI38: 250 | AL38: =IF(ISBLANK(AK38),"",AK38<AG38) | AO38: Chloride is the anionic (negatively charged) form of chlorine, a chemical element and halogen. It is a common ion found in rocks, soils, and is the major component of dietary salt (sodium chloride), which is the salt found in the ocean. Chloride is found in road salt and a large number of industrial and commercial chemicals. Chloride can be introduced into drinking water by dissolution of natural mineral deposits, infiltration of seawater into a well, and discharge from industrial processes or sewage. Chloride is naturally present in drinking water systems treated with free chlorine, which produces chloride as a product of certain reactions. Some other water treatment chemicals, including some water softener salts, also contain chloride. Elevated chloride in water may contribute to a salty taste. | AU38: TRUE | AW38: TRUE
A39: Free chlorine | B39: chlorine, free | C39: NA | G39: Inorganic compound | P39: 0 | Q39: 0 | R39: 0 | S39: 1 | T39: 0 | AD39: TRUE | AE39: FALSE | AF39: 0.8 | AG39: 0.8 | AH39: MRDL(G), not MCL(G) | AL39: =IF(ISBLANK(AK39),"",AK39<AG39) | AO39: Chlorine is added to drinking water to kill microbes that can cause disease. Excessive chlorine can be hazardous both directly and through increased disinfection byproduct formation. | AT39: TRUE | AU39: TRUE
A40: Chlorite | B40: chlorite | C40: ClO2 − | E40: 14998-27-7 | F40: QBWCMBCROVPCKQ-UHFFFAOYSA-M | G40: Inorganic compound | L40: TRUE | P40: 0 | Q40: 0 | R40: 0 | S40: 1 | T40: 0 | AD40: TRUE | AE40: FALSE | AF40: 0.8 | AG40: 1 | AL40: =IF(ISBLANK(AK40),"",AK40<AG40) | AO40: Chlorite is an ion composed of chlorine and oxygen. It is used as a precursor to chlorine dioxide, which is used in water disinfection, and produced as a disinfection byproduct when chlorine dioxide is used to treat water. Note: While the term “chlorite” is also used to describe a group of minerals, these minerals do not contain any form of chlorine and are instead named for their green color (from the Greek chloros, meaning “green”). | AU40: TRUE | AW40: TRUE
...

Sheet Footnotes
A1: id | B1: text
A2: A | B2: A comprehensive analysis of the polycyclic aromatic hydrocarbon content of jet fuels carried out by L.A. Shumway in 2000 found that the major PAHs in JP-5 are, in order of abundance, C1-naphthalenes, C2-naphthalenes, naphthalene, C3-naphthalenes, biphenyl, and C4-naphthalenes. Of the compounds annotated with this footnote, only anthracene (0.02%), fluoranthene (0.02%), fluorene (0.4%), and phenanthrene (0.1%) were found to be present in JP-5, the rest were not detected.
A3: B | B3: A comprehensive analysis of the trace metal content of jet fuels carried out by L.A. Shumway in 2000 analyzed jet fuel samples for a panel of 38 metals, including those annotated with this footnote that show up in Red Hill datasets. Of those that were monitored in a Red Hill dataset, only barium, chromium, copper, lead, and nickel were detected in JP-5 in this work.
A4: C | B4: The Extended Drinking Water Monitoring Plan (June 2024) incorrectly lists the CASRNs for these compounds as those for the metallic elements. However, only the ionic forms are expected to be present in drinking water, and they have different CASRNs and InChIKeys. For compatibility we have included the CASRN for the metallic form of each impacted element, but we have only included the InChIKeys for the ionic form(s).
A5: D | B5: This compound is not an active ingredient of a pesticide, but is present in pesticide products as a byproduct of manufacturing and is thus found in areas where pesticide contamination has occurred.
